Workbook

Sheet Graphic
B3: 1st Week | D3: ='ABC GRADE'!D4 -> 44743 | F3: ='ABC GRADE'!E4 -> 44746 | N3: =L3+1 -> 1 | P3: TOTAL | S3: 2nd Week | U3: ='ABC GRADE'!M4 -> 44388 | W3: =U3+1 -> 44389 | Y3: =W3+1 -> 44390 | AA3: =Y3+1 -> 44391 | AC3: =AA3+1 -> 44392 | AE3: =AC3+1 -> 44393 | AG3: TOTAL | AJ3: 3rd Week | AL3: ='ABC GRADE'!U4 -> 44760 | AN3: =AL3+1 -> 44761 | AP3: =AN3+1 -> 44762 | AR3: =AP3+1 -> 44763 | AT3: =AR3+1 -> 44764 | AV3: =AT3+1 -> 44765 | AX3: TOTAL | BA3: 4th Week | BC3: ='ABC GRADE'!AC4 -> 44402 | BE3: =BC3+1 -> 44403 | BG3: =BE3+1 -> 44404 | BI3: =BG3+1 -> 44405 | BK3: =BI3+1 -> 44406 | BM3: =BK3+1 -> 44407 | BO3: TOTAL | BR3: 5th Week | BT3: ='ABC GRADE'!AK4 -> 44009 | BV3: =BT3+1 -> 44010 | BX3: =BV3+1 -> 44011 | BZ3: =BX3+1 -> 44012 | CB3: =BZ3+1 -> 44013 | CD3: =CB3+1 -> 44014 | CF3: TOTAL
D4: Prs | E4: % | F4: Prs | G4: % | H4: Prs | I4: % | J4: Prs | K4: % | L4: Prs | M4: % | N4: Prs | O4: % | P4: Prs | Q4: % | U4: Prs | V4: % | W4: Prs | X4: % | Y4: Prs | Z4: % | AA4: Prs | AB4: % | AC4: Prs | AD4: % | AE4: Prs | AF4: % | AG4: Prs | AH4: % | AL4: Prs | AM4: % | AN4: Prs | AO4: % | AP4: Prs | AQ4: % | AR4: Prs | AS4: % | AT4: Prs | AU4: % | AV4: Prs | AW4: % | AX4: Prs | AY4: % | BC4: Prs | BD4: % | BE4: Prs | BF4: % | BG4: Prs | BH4: % | BI4: Prs | BJ4: % | BK4: Prs | BL4: % | BM4: Prs | BN4: % | BO4: Prs | BP4: % | BT4: Prs | BU4: % | BV4: Prs | BW4: % | BX4: Prs | BY4: % | BZ4: Prs | CA4: % | CB4: Prs | CC4: % | CD4: Prs | CE4: % | CF4: Prs | CG4: %
C5: A-Grade | D5: ='ABC GRADE'!D20 -> 0 | E5: =D5/D8 -> 0 | F5: ='ABC GRADE'!E20 -> 90 | G5: =F5/F8 -> 0.97826087 | H5: ='ABC GRADE'!F20 -> 290 | I5: =H5/H8 -> 0.93548387 | J5: ='ABC GRADE'!G20 -> 460 | K5: =J5/J8 -> 0.99459459 | L5: ='ABC GRADE'!H20 -> 330 | M5: =L5/L8 -> 0.98214286 | N5: ='ABC GRADE'!I20 -> 340 | O5: =N5/N8 -> 0.98550725 | P5: =+D5+F5+H5+J5+L5+N5 -> 1510 | Q5: =P5/P8 -> 0.9767141 | T5: A-Grade | U5: ='ABC GRADE'!M20 -> 310 | V5: =U5/U8 -> 0.99518459 | W5: ='ABC GRADE'!N20 -> 380 | X5: =W5/W8 -> 0.99087353 | Y5: ='ABC GRADE'!O20 -> 776 | Z5: =Y5/Y8 -> 0.98539683 | AA5: ='ABC GRADE'!P20 -> 360 | AB5: =AA5/AA8 -> 0.98765432 | AC5: ='ABC GRADE'!Q20 -> 0 | AD5: =AC5/AC8 -> #DIV/0! | AE5: ='ABC GRADE'!R20 -> 0 | AF5: =AE5/AE8 -> #DIV/0! | AG5: =+U5+W5+Y5+AA5+AC5+AE5 -> 1826 | AH5: =AG5/AG8 -> 0.98863021 | AK5: A-Grade | AL5: ='ABC GRADE'!U20 -> 0 | AM5: =AL5/AL8 -> #DIV/0! | AN5: ='ABC GRADE'!V20 -> 0 | AO5: =AN5/AN8 -> #DIV/0! | AP5: ='ABC GRADE'!W20 -> 0 | AQ5: =AP5/AP8 -> #DIV/0! | AR5: ='ABC GRADE'!X20 -> 0 | AS5: =AR5/AR8 -> #DIV/0! | AT5: ='ABC GRADE'!Y20 -> 0 | AU5: =AT5/AT8 -> #DIV/0! | AV5: ='ABC GRADE'!Z20 -> 0 | AW5: =AV5/AV8 -> #DIV/0! | AX5: =+AL5+AN5+AP5+AR5+AT5+AV5 -> 0 | AY5: =AX5/AX8 -> #DIV/0! | BB5: A-Grade | BC5: ='ABC GRADE'!AC20 -> 0 | BD5: =BC5/BC8 -> #DIV/0! | BE5: ='ABC GRADE'!AD20 -> 0 | BF5: =BE5/BE8 -> #DIV/0! | BG5: ='ABC GRADE'!AE20 -> 0 | BH5: =BG5/BG8 -> #DIV/0! | BI5: ='ABC GRADE'!AF20 -> 0 | BJ5: =BI5/BI8 -> #DIV/0! | BK5: ='ABC GRADE'!AG20 -> 0 | BL5: =BK5/BK8 -> #DIV/0! | BM5: ='ABC GRADE'!AH20 -> 0 | BN5: =BM5/BM8 -> #DIV/0! | BO5: =+BC5+BE5+BG5+BI5+BK5+BM5 -> 0 | BP5: =BO5/BO8 -> #DIV/0! | BS5: A-Grade | BT5: ='ABC GRADE'!AK18 -> 0 | BU5: =BT5/BT8 -> #DIV/0! | BV5: ='ABC GRADE'!AL18 -> 0 | BW5: =BV5/BV8 -> #DIV/0! | BX5: ='ABC GRADE'!AM18 -> 0 | BY5: =BX5/BX8 -> #DIV/0! | BZ5: ='ABC GRADE'!AN18 -> 0 | CA5: =BZ5/BZ8 -> #DIV/0! | CB5: ='ABC GRADE'!AO18 -> 0 | CC5: =CB5/CB8 -> #DIV/0! | CD5: ='ABC GRADE'!AP18 -> 0 | CE5: =CD5/CD8 -> #DIV/0! | CF5: =+BT5+BV5+BX5+BZ5+CB5+CD5 -> 0 | CG5: =CF5/CF8 -> #DIV/0!
C6: B-Grade | D6: ='ABC GRADE'!D8 -> 0 | E6: =D6/D8 -> 0 | F6: ='ABC GRADE'!E8 -> 0 | G6: =F6/F8 -> 0 | H6: ='ABC GRADE'!F8 -> 0 | I6: =H6/H8 -> 0 | J6: ='ABC GRADE'!G8 -> 0 | K6: =J6/J8 -> 0 | L6: ='ABC GRADE'!H8 -> 0 | M6: =L6/L8 -> 0 | N6: ='ABC GRADE'!I8 -> 0 | O6: =N6/N8 -> 0 | P6: =+D6+F6+H6+J6+L6+N6 -> 0 | Q6: =P6/P8 -> 0 | T6: B-Grade | U6: ='ABC GRADE'!M8 -> 0 | V6: =U6/U8 -> 0 | W6: ='ABC GRADE'!N8 -> 0 | X6: =W6/W8 -> 0 | Y6: ='ABC GRADE'!O8 -> 0 | Z6: =Y6/Y8 -> 0 | AA6: ='ABC GRADE'!P8 -> 0 | AB6: =AA6/AA8 -> 0 | AC6: ='ABC GRADE'!Q8 -> 0 | AD6: =AC6/AC8 -> #DIV/0! | AE6: ='ABC GRADE'!R8 -> 0 | AF6: =AE6/AE8 -> #DIV/0! | AG6: =+U6+W6+Y6+AA6+AC6+AE6 -> 0 | AH6: =AG6/AG8 -> 0 | AK6: B-Grade | AL6: ='ABC GRADE'!U8 -> 0 | AM6: =AL6/AL8 -> #DIV/0! | AN6: ='ABC GRADE'!V8 -> 0 | AO6: =AN6/AN8 -> #DIV/0! | AP6: ='ABC GRADE'!W8 -> 0 | AQ6: =AP6/AP8 -> #DIV/0! | AR6: ='ABC GRADE'!X8 -> 0 | AS6: =AR6/AR8 -> #DIV/0! | AT6: ='ABC GRADE'!Y8 -> 0 | AU6: =AT6/AT8 -> #DIV/0! | AV6: ='ABC GRADE'!Z8 -> 0 | AW6: =AV6/AV8 -> #DIV/0! | AX6: =+AL6+AN6+AP6+AR6+AT6+AV6 -> 0 | AY6: =AX6/AX8 -> #DIV/0! | BB6: B-Grade | BC6: ='ABC GRADE'!AC8 -> 0 | BD6: =BC6/BC8 -> #DIV/0! | BE6: ='ABC GRADE'!AD8 -> 0 | BF6: =BE6/BE8 -> #DIV/0! | BG6: ='ABC GRADE'!AE8 -> 0 | BH6: =BG6/BG8 -> #DIV/0! | BI6: ='ABC GRADE'!AF8 -> 0 | BJ6: =BI6/BI8 -> #DIV/0! | BK6: ='ABC GRADE'!AG6 -> 0 | BL6: =BK6/BK8 -> #DIV/0! | BM6: ='ABC GRADE'!AH8 -> 0 | BN6: =BM6/BM8 -> #DIV/0! | BO6: =+BC6+BE6+BG6+BI6+BK6+BM6 -> 0 | BP6: =BO6/BO8 -> #DIV/0! | BS6: B-Grade | BT6: ='ABC GRADE'!AK8 -> 0 | BU6: =BT6/BT8 -> #DIV/0! | BV6: ='ABC GRADE'!AL8 -> 0 | BW6: =BV6/BV8 -> #DIV/0! | BX6: ='ABC GRADE'!AM8 -> 0 | BY6: =BX6/BX8 -> #DIV/0! | BZ6: ='ABC GRADE'!AN8 -> 0 | CA6: =BZ6/BZ8 -> #DIV/0! | CB6: ='ABC GRADE'!AO8 -> 0 | CC6: =CB6/CB8 -> #DIV/0! | CD6: ='ABC GRADE'!AP8 -> 0 | CE6: =CD6/CD8 -> #DIV/0! | CF6: =+BT6+BV6+BX6+BZ6+CB6+CD6 -> 0 | CG6: =CF6/CF8 -> #DIV/0!
C7: C-Grade | D7: ='ABC GRADE'!D16 -> 0.5 | E7: =D7/D8 -> 1 | F7: ='ABC GRADE'!E16 -> 2 | G7: =F7/F8 -> 0.02173913 | H7: ='ABC GRADE'!F16 -> 20 | I7: =H7/H8 -> 0.064516129 | J7: ='ABC GRADE'!G16 -> 2.5 | K7: =J7/J8 -> 0.0054054054 | L7: ='ABC GRADE'!H16 -> 6 | M7: =L7/L8 -> 0.017857143 | N7: ='ABC GRADE'!I16 -> 5 | O7: =N7/N8 -> 0.014492754 | P7: =+D7+F7+H7+J7+L7+N7 -> 36 | Q7: =P7/P8 -> 0.023285899 | T7: C-Grade | U7: ='ABC GRADE'!M16 -> 1.5 | V7: =U7/U8 -> 0.0048154093 | W7: ='ABC GRADE'!N16 -> 3.5 | X7: =W7/W8 -> 0.0091264668 | Y7: ='ABC GRADE'!O16 -> 11.5 | Z7: =Y7/Y8 -> 0.014603175 | AA7: ='ABC GRADE'!P16 -> 4.5 | AB7: =AA7/AA8 -> 0.012345679 | AC7: ='ABC GRADE'!Q16 -> 0 | AD7: =AC7/AC8 -> #DIV/0! | AE7: ='ABC GRADE'!R16 -> 0 | AF7: =AE7/AE8 -> #DIV/0! | AG7: =+U7+W7+Y7+AA7+AC7+AE7 -> 21 | AH7: =AG7/AG8 -> 0.011369789 | AK7: C-Grade | AL7: ='ABC GRADE'!U16 -> 0 | AM7: =AL7/AL8 -> #DIV/0! | AN7: ='ABC GRADE'!V16 -> 0 | AO7: =AN7/AN8 -> #DIV/0! | AP7: ='ABC GRADE'!W16 -> 0 | AQ7: =AP7/AP8 -> #DIV/0! | AR7: ='ABC GRADE'!X16 -> 0 | AS7: =AR7/AR8 -> #DIV/0! | AT7: ='ABC GRADE'!Y16 -> 0 | AU7: =AT7/AT8 -> #DIV/0! | AV7: ='ABC GRADE'!Z16 -> 0 | AW7: =AV7/AV8 -> #DIV/0! | AX7: =+AL7+AN7+AP7+AR7+AT7+AV7 -> 0 | AY7: =AX7/AX8 -> #DIV/0! | BB7: C-Grade | BC7: ='ABC GRADE'!AC16 -> 0 | BD7: =BC7/BC8 -> #DIV/0! | BE7: ='ABC GRADE'!AD16 -> 0 | BF7: =BE7/BE8 -> #DIV/0! | BG7: ='ABC GRADE'!AE16 -> 0 | BH7: =BG7/BG8 -> #DIV/0! | BI7: ='ABC GRADE'!AF16 -> 0 | BJ7: =BI7/BI8 -> #DIV/0! | BK7: ='ABC GRADE'!AG16 -> 0 | BL7: =BK7/BK8 -> #DIV/0! | BM7: ='ABC GRADE'!AH16 -> 0 | BN7: =BM7/BM8 -> #DIV/0! | BO7: =+BC7+BE7+BG7+BI7+BK7+BM7 -> 0 | BP7: =BO7/BO8 -> #DIV/0! | BS7: C-Grade | BT7: ='ABC GRADE'!AK16 -> 0 | BU7: =BT7/BT8 -> #DIV/0! | BV7: ='ABC GRADE'!AL16 -> 0 | BW7: =BV7/BV8 -> #DIV/0! | BX7: ='ABC GRADE'!AM16 -> 0 | BY7: =BX7/BX8 -> #DIV/0! | BZ7: ='ABC GRADE'!AN16 -> 0 | CA7: =BZ7/BZ8 -> #DIV/0! | CB7: ='ABC GRADE'!AO16 -> 0 | CC7: =CB7/CB8 -> #DIV/0! | CD7: ='ABC GRADE'!AP16 -> 0 | CE7: =CD7/CD8 -> #DIV/0! | CF7: =+BT7+BV7+BX7+BZ7+CB7+CD7 -> 0 | CG7: =CF7/CF8 -> #DIV/0!
C8: Total Production | D8: =SUM(D5:D7) -> 0.5 | F8: =SUM(F5:F7) -> 92 | H8: =SUM(H5:H7) -> 310 | J8: =SUM(J5:J7) -> 462.5 | L8: =SUM(L5:L7) -> 336 | N8: =SUM(N5:N7) -> 345 | P8: =SUM(P5:P7) -> 1546 | T8: GRAND TOTAL | U8: =SUM(U5:U7) -> 311.5 | W8: =SUM(W5:W7) -> 383.5 | Y8: =SUM(Y5:Y7) -> 787.5 | AA8: =SUM(AA5:AA7) -> 364.5 | AC8: =SUM(AC5:AC7) -> 0 | AE8: =SUM(AE5:AE7) -> 0 | AG8: =SUM(AG5:AG7) -> 1847 | AK8: GRAND TOTAL | AL8: =SUM(AL5:AL7) -> 0 | AN8: =SUM(AN5:AN7) -> 0 | AP8: =SUM(AP5:AP7) -> 0 | AR8: =SUM(AR5:AR7) -> 0 | AT8: =SUM(AT5:AT7) -> 0 | AV8: =SUM(AV5:AV7) -> 0 | AX8: =SUM(AX5:AX7) -> 0 | BB8: GRAND TOTAL | BC8: =SUM(BC5:BC7) -> 0 | BE8: =SUM(BE5:BE7) -> 0 | BG8: =SUM(BG5:BG7) -> 0 | BI8: =SUM(BI5:BI7) -> 0 | BK8: =SUM(BK5:BK7) -> 0 | BM8: =SUM(BM5:BM7) -> 0 | BO8: =SUM(BO5:BO7) -> 0 | BS8: GRAND TOTAL | BT8: =SUM(BT5:BT7) -> 0 | BV8: =SUM(BV5:BV7) -> 0 | BX8: =SUM(BX5:BX7) -> 0 | BZ8: =SUM(BZ5:BZ7) -> 0 | CB8: =SUM(CB5:CB7) -> 0 | CD8: =SUM(CD5:CD7) -> 0 | CF8: =SUM(BT8:CE8) -> 0
B27: monthly | D27: 1st Week | F27: 2nd Week | H27: 3rd Week | J27: 4th Week | L27: 5th week | N27: TOTAL
D28: Prs | E28: % | F28: Prs | G28: % | H28: Prs | I28: % | J28: Prs | K28: % | L28: Prs | M28: % | N28: Prs | O28: %
C29: A-Grade | D29: =P5 -> 1510 | E29: =D29/D32 -> 0.9767141 | F29: =AG5 -> 1826 | G29: =F29/F32 -> 0.98863021 | H29: =AX5 -> 0 | I29: =H29/H32 -> #DIV/0! | J29: =BO5 -> 0 | K29: =J29/J32 -> #DIV/0! | L29: =CF5 -> 0 | M29: =L29/L32 -> #DIV/0! | N29: =SUM(D29,F29,H29,J29,J29) -> 3336 | O29: =N29/N32 -> 0.98320071
C30: B-Grade | D30: =P6 -> 0 | E30: =D30/D32 -> 0 | F30: =AG6 -> 0 | G30: =F30/F32 -> 0 | H30: =AX6 -> 0 | I30: =H30/H32 -> #DIV/0! | J30: =BO6 -> 0 | K30: =J30/J32 -> #DIV/0! | L30: =CF6 -> 0 | M30: =L30/L32 -> #DIV/0! | N30: =SUM(D30,F30,H30,J30,J30) -> 0 | O30: =N30/N32 -> 0
C31: C-Grade | D31: =P7 -> 36 | E31: =D31/D32 -> 0.023285899 | F31: =AG7 -> 21 | G31: =F31/F32 -> 0.011369789 | H31: =AX7 -> 0 | I31: =H31/H32 -> #DIV/0! | J31: =BO7 -> 0 | K31: =J31/J32 -> #DIV/0! | L31: =CF7 -> 0 | M31: =L31/L32 -> #DIV/0! | N31: =SUM(D31,F31,H31,J31,J31) -> 57 | O31: =N31/N32 -> 0.016799293
C32: Total Production | D32: =SUM(D29:D31) -> 1546 | F32: =SUM(F29:F31) -> 1847 | H32: =SUM(H29:H31) -> 0 | J32: =SUM(J29:J31) -> 0 | L32: =SUM(L29:L31) -> 0 | N32: =SUM(N29:N31) -> 3393

Sheet ABC GRADE
D2: DAILY ABC GRADE PRODUCTION
D3: WEEK 1 | M3: WEEK 2 | U3: WEEK 3 | AC3: WEEK 4 | AK3: WEEK 5 | AS3: TOTAL ALL
D4: 44743 | E4: 44746 | F4: =E4+1 -> 44747 | G4: =F4+1 -> 44748 | H4: =G4+1 -> 44749 | I4: =H4+1 -> 44750 | K4: TOTAL | M4: 44388 | N4: =M4+1 -> 44389 | O4: =N4+1 -> 44390 | P4: =O4+1 -> 44391 | Q4: =P4+1 -> 44392 | R4: =Q4+1 -> 44393 | S4: TOTAL | U4: 44760 | V4: =U4+1 -> 44761 | W4: =V4+1 -> 44762 | X4: =W4+1 -> 44763 | Y4: =X4+1 -> 44764 | Z4: =Y4+1 -> 44765 | AA4: TOTAL | AC4: 44402 | AD4: =AC4+1 -> 44403 | AE4: =AD4+1 -> 44404 | AF4: =AE4+1 -> 44405 | AG4: =AF4+1 -> 44406 | AH4: =AG4+1 -> 44407 | AI4: TOTAL | AK4: 44009 | AL4: =AK4+1 -> 44010 | AM4: =AL4+1 -> 44011 | AN4: =AM4+1 -> 44012 | AQ4: TOTAL
B5: B Grade | C5: Line - | D5: 0 | E5: 0 | F5: 0 | G5: 0 | H5: 0 | I5: 0 | K5: =SUM(D5:J5) -> 0 | L5: =K5/K23 -> 0 | M5: 0 | N5: 0 | O5: 0 | P5: 0 | Q5: 0 | R5: 0 | S5: =SUM(M5:R5) -> 0 | T5: =S5/S23 -> 0 | U5: 0 | V5: 0 | W5: 0 | X5: 0 | Y5: 0 | Z5: 0 | AA5: =SUM(U5:Z5) -> 0 | AB5: =AA5/AA23 -> #DIV/0! | AC5: 0 | AD5: 0 | AE5: 0 | AF5: 0 | AG5: 0 | AI5: =SUM(AC5:AH5) -> 0 | AJ5: =AI5/AI23 -> #DIV/0! | AK5: 0 | AL5: 0 | AM5: 0 | AN5: 0 | AO5: 0 | AQ5: =SUM(AK5:AP5) -> 0 | AR5: =AQ5/AQ23 -> #DIV/0! | AS5: =+K5+S5+AA5+AI5+AQ5 -> 0 | AT5: =AS5/AS23 -> 0
C6: Line 6 | D6: 0 | E6: 0 | F6: 0 | G6: 0 | H6: 0 | I6: 0 | J6: 0 | K6: =SUM(D6:J6) -> 0 | L6: =K6/K23 -> 0 | M6: 0 | N6: 0 | O6: 0 | P6: 0 | Q6: 0 | R6: 0 | S6: =SUM(M6:R6) -> 0 | T6: =S6/S23 -> 0 | U6: 0 | V6: 0 | W6: 0 | X6: 0 | Y6: 0 | Z6: 0 | AA6: =SUM(U6:Z6) -> 0 | AB6: =AA6/AA23 -> #DIV/0! | AC6: 0 | AD6: 0 | AE6: 0 | AF6: 0 | AG6: 0 | AH6: 0 | AI6: =SUM(AC6:AH6) -> 0 | AJ6: =AI6/AI23 -> #DIV/0! | AK6: 0 | AL6: 0 | AM6: 0 | AN6: 0 | AO6: 0 | AP6: 0 | AQ6: =SUM(AK6:AP6) -> 0 | AR6: =AQ6/AQ23 -> #DIV/0! | AS6: =+K6+S6+AA6+AI6+AQ6 -> 0 | AT6: =AS6/AS23 -> 0
C7: Cold Cement | D7: 0 | E7: 0 | F7: 0 | G7: 0 | H7: 0 | I7: 0 | J7: 0 | K7: =SUM(D7:J7) -> 0 | L7: =K7/K23 -> 0 | M7: 0 | N7: 0 | O7: 0 | P7: 0 | Q7: 0 | R7: 0 | S7: =SUM(M7:R7) -> 0 | T7: =S7/S23 -> 0 | U7: 0 | V7: 0 | W7: 0 | X7: 0 | Y7: 0 | Z7: 0 | AA7: =SUM(U7:Z7) -> 0 | AB7: =AA7/AA23 -> #DIV/0! | AC7: 0 | AD7: 0 | AE7: 0 | AF7: 0 | AG7: 0 | AH7: 0 | AI7: =SUM(AC7:AH7) -> 0 | AJ7: =AI7/AI23 -> #DIV/0! | AK7: 0 | AL7: 0 | AM7: 0 | AN7: 0 | AO7: 0 | AQ7: =SUM(AK7:AP7) -> 0 | AR7: =AQ7/AQ23 -> #DIV/0! | AS7: =+K7+S7+AA7+AI7+AQ7 -> 0 | AT7: =AS7/AS23 -> 0
C8: Total | D8: =SUM(D5:D7) -> 0 | E8: =SUM(E5:E7) -> 0 | F8: =SUM(F5:F7) -> 0 | G8: =SUM(G5:G7) -> 0 | H8: =SUM(H5:H7) -> 0 | I8: =SUM(I5:I7) -> 0 | J8: =SUM(J5:J7) -> 0 | K8: =SUM(D8:J8) -> 0 | L8: =K8/K23 -> 0 | M8: =SUM(M5:M7) -> 0 | N8: =SUM(N5:N7) -> 0 | O8: =SUM(O5:O7) -> 0 | P8: =SUM(P5:P7) -> 0 | Q8: =SUM(Q5:Q7) -> 0 | R8: =SUM(R5:R7) -> 0 | S8: =SUM(M8:R8) -> 0 | T8: =S8/S23 -> 0 | U8: =SUM(U5:U7) -> 0 | V8: =SUM(V5:V7) -> 0 | W8: =SUM(W5:W7) -> 0 | X8: =SUM(X5:X7) -> 0 | Y8: =SUM(Y5:Y7) -> 0 | Z8: =SUM(Z5:Z7) -> 0 | AA8: =SUM(U8:Z8) -> 0 | AB8: =AA8/AA23 -> #DIV/0! | AC8: =SUM(AC5:AC7) -> 0 | AD8: =SUM(AD5:AD7) -> 0 | AE8: =SUM(AE5:AE7) -> 0 | AF8: =SUM(AF5:AF7) -> 0 | AG8: =SUM(AG5:AG7) -> 0 | AH8: =SUM(AH5:AH7) -> 0 | AI8: =SUM(AC8:AH8) -> 0 | AJ8: =AI8/AI23 -> #DIV/0! | AK8: =SUM(AK5:AK7) -> 0 | AL8: =SUM(AL5:AL7) -> 0 | AM8: =SUM(AM5:AM7) -> 0 | AN8: =SUM(AN5:AN7) -> 0 | AO8: =SUM(AO5:AO7) -> 0 | AP8: =SUM(AP5:AP7) -> 0 | AQ8: =SUM(AK8:AP8) -> 0 | AR8: =AQ8/AQ23 -> #DIV/0! | AS8: =+K8+S8+AA8+AI8+AQ8 -> 0 | AT8: =AS8/AS23 -> 0
B9: Donasi | C9: Line 4 | D9: 0 | E9: 0 | F9: 0 | G9: 0 | H9: 0 | I9: 0 | K9: =SUM(D9:J9) -> 0 | L9: =K9/K23 -> 0 | M9: 0 | N9: 0 | O9: 0 | P9: 0 | Q9: 0 | R9: 0 | S9: =SUM(M9:R9) -> 0 | T9: =S9/S23 -> 0 | U9: 0 | V9: 0 | W9: 0 | X9: 0 | Y9: 0 | Z9: 0 | AA9: =SUM(U9:Z9) -> 0 | AB9: =AA9/AA23 -> #DIV/0! | AC9: 0 | AD9: 0 | AE9: 0 | AF9: 0 | AG9: 0 | AI9: =SUM(AC9:AH9) -> 0 | AJ9: =AI9/AI23 -> #DIV/0! | AK9: 0 | AL9: 0 | AM9: 0 | AN9: 0 | AO9: 0 | AQ9: =SUM(AK9:AP9) -> 0 | AR9: =AQ9/AQ23 -> #DIV/0! | AS9: =+K9+S9+AA9+AI9+AQ9 -> 0 | AT9: =AS9/AS23 -> 0
C10: Line 5 | D10: 0 | E10: 0 | F10: 0 | G10: 0 | H10: 0 | I10: 0 | K10: =SUM(D10:J10) -> 0 | L10: =K10/K23 -> 0 | M10: 0 | N10: 0 | O10: 0 | P10: 0 | Q10: 0 | R10: 0 | S10: =SUM(M10:R10) -> 0 | T10: =S10/S23 -> 0 | U10: 0 | V10: 0 | W10: 0 | Z10: 0 | AA10: =SUM(U10:Z10) -> 0 | AB10: =AA10/AA23 -> #DIV/0! | AC10: 0 | AD10: 0 | AE10: 0 | AF10: 0 | AG10: 0 | AH10: 0 | AI10: =SUM(AC10:AH10) -> 0 | AJ10: =AI10/AI23 -> #DIV/0! | AK10: 0 | AL10: 0 | AM10: 0 | AN10: 0 | AO10: 0 | AP10: 0 | AQ10: =SUM(AK10:AP10) -> 0 | AR10: =AQ10/AQ23 -> #DIV/0! | AS10: =+K10+S10+AA10+AI10+AQ10 -> 0 | AT10: =AS10/AS23 -> 0
C11: Line - | D11: 0 | E11: 0 | F11: 0 | G11: 0 | H11: 0 | I11: 0 | K11: =SUM(D11:J11) -> 0 | L11: =K11/K23 -> 0 | M11: 0 | N11: 0 | O11: 0 | P11: 0 | Q11: 0 | R11: 0 | S11: =SUM(M11:R11) -> 0 | T11: =S11/S23 -> 0 | U11: 0 | V11: 0 | W11: 0 | X11: 0 | Y11: 0 | Z11: 0 | AA11: =SUM(U11:Z11) -> 0 | AB11: =AA11/AA23 -> #DIV/0! | AC11: 0 | AD11: 0 | AE11: 0 | AF11: 0 | AG11: 0 | AI11: =SUM(AC11:AH11) -> 0 | AJ11: =AI11/AI23 -> #DIV/0! | AK11: 0 | AL11: 0 | AM11: 0 | AN11: 0 | AO11: 0 | AQ11: =SUM(AK11:AP11) -> 0 | AR11: =AQ11/AQ23 -> #DIV/0! | AS11: =+K11+S11+AA11+AI11+AQ11 -> 0 | AT11: =AS11/AS23 -> 0
C12: Total | D12: =SUM(D9:D11) -> 0 | E12: =SUM(E9:E11) -> 0 | F12: =SUM(F9:F11) -> 0 | G12: =SUM(G9:G11) -> 0 | H12: =SUM(H9:H11) -> 0 | I12: =SUM(I9:I11) -> 0 | J12: =SUM(J9:J11) -> 0 | K12: =SUM(D12:J12) -> 0 | L12: =K12/K23 -> 0 | M12: =SUM(M9:M11) -> 0 | N12: =SUM(N9:N11) -> 0 | O12: =SUM(O9:O11) -> 0 | P12: =SUM(P9:P11) -> 0 | Q12: =SUM(Q9:Q11) -> 0 | R12: =SUM(R9:R11) -> 0 | S12: =SUM(M12:R12) -> 0 | T12: =S12/S23 -> 0 | U12: =SUM(U9:U11) -> 0 | V12: =SUM(V9:V11) -> 0 | W12: =SUM(W9:W11) -> 0 | X12: =SUM(X9:X11) -> 0 | Y12: =SUM(Y9:Y11) -> 0 | Z12: =SUM(Z9:Z11) -> 0 | AA12: =SUM(U12:Z12) -> 0 | AB12: =AA12/AA23 -> #DIV/0! | AC12: =SUM(AC9:AC11) -> 0 | AD12: =SUM(AD9:AD11) -> 0 | AE12: =SUM(AE9:AE11) -> 0 | AF12: =SUM(AF9:AF11) -> 0 | AG12: =SUM(AG9:AG11) -> 0 | AH12: =SUM(AH9:AH11) -> 0 | AI12: =SUM(AC12:AH12) -> 0 | AJ12: =AI12/AI23 -> #DIV/0! | AK12: =SUM(AK9:AK11) -> 0 | AL12: =SUM(AL9:AL11) -> 0 | AM12: =SUM(AM9:AM11) -> 0 | AN12: =SUM(AN9:AN11) -> 0 | AO12: =SUM(AO9:AO11) -> 0 | AP12: =SUM(AP9:AP11) -> 0 | AQ12: =SUM(AK12:AP12) -> 0 | AR12: =AQ12/AQ23 -> #DIV/0! | AS12: =+K12+S12+AA12+AI12+AQ12 -> 0 | AT12: =AS12/AS23 -> 0
B13: C Grade | C13: Line - | D13: 0 | E13: 0 | F13: 0 | G13: 0 | H13: 0 | I13: 0 | K13: =SUM(D13:J13) -> 0 | L13: =K13/K23 -> 0 | M13: 0 | N13: 0 | O13: 0 | P13: 0 | Q13: 0 | R13: 0 | S13: =SUM(M13:R13) -> 0 | T13: =S13/S23 -> 0 | U13: 0 | V13: 0 | W13: 0 | X13: 0 | Y13: 0 | Z13: 0 | AA13: =SUM(U13:Z13) -> 0 | AB13: =AA13/AA23 -> #DIV/0! | AC13: 0 | AD13: 0 | AE13: 0 | AF13: 0 | AG13: 0 | AH13: 0 | AI13: =SUM(AC13:AH13) -> 0 | AJ13: =AI13/AI23 -> #DIV/0! | AK13: 0 | AL13: 0 | AM13: 0 | AN13: 0 | AO13: 0 | AP13: 0 | AQ13: =SUM(AK13:AP13) -> 0 | AR13: =AQ13/AQ23 -> #DIV/0! | AS13: =+K13+S13+AA13+AI13+AQ13 -> 0 | AT13: =AS13/AS23 -> 0
C14: Line 6 | D14: 0.5 | E14: 2 | F14: 2 | G14: 0.5 | H14: 1 | I14: 3 | K14: =SUM(D14:J14) -> 9 | L14: =K14/K23 -> 0.0058214748 | M14: 0 | N14: 0 | O14: 11 | P14: 2 | Q14: 0 | R14: 0 | S14: =SUM(M14:R14) -> 13 | T14: =S14/S23 -> 0.0070384407 | U14: 0 | V14: 0 | W14: 0 | X14: 0 | Y14: 0 | Z14: 0 | AA14: =SUM(U14:Z14) -> 0 | AB14: =AA14/AA23 -> #DIV/0! | AC14: 0 | AD14: 0 | AE14: 0 | AF14: 0 | AG14: 0 | AH14: 0 | AI14: =SUM(AC14:AH14) -> 0 | AJ14: =AI14/AI23 -> #DIV/0! | AK14: 0 | AL14: 0 | AM14: 0 | AN14: 0 | AO14: 0 | AP14: 0 | AQ14: =SUM(AK14:AP14) -> 0 | AR14: =AQ14/AQ23 -> #DIV/0! | AS14: =+K14+S14+AA14+AI14+AQ14 -> 22 | AT14: =AS14/AS23 -> 0.0064839375
C15: Cold Cement | D15: 0 | E15: 0 | F15: 18 | G15: 2 | H15: 5 | I15: 2 | K15: =SUM(D15:J15) -> 27 | L15: =K15/K23 -> 0.017464424 | M15: 1.5 | N15: 3.5 | O15: 0.5 | P15: 2.5 | Q15: 0 | R15: 0 | S15: =SUM(M15:R15) -> 8 | T15: =S15/S23 -> 0.0043313481 | U15: 0 | V15: 0 | W15: 0 | X15: 0 | Y15: 0 | Z15: 0 | AA15: =SUM(U15:Z15) -> 0 | AB15: =AA15/AA23 -> #DIV/0! | AC15: 0 | AD15: 0 | AE15: 0 | AF15: 0 | AG15: 0 | AH15: 0 | AI15: =SUM(AC15:AH15) -> 0 | AJ15: =AI15/AI23 -> #DIV/0! | AK15: 0 | AL15: 0 | AM15: 0 | AN15: 0 | AO15: 0 | AP15: 0 | AQ15: =SUM(AK15:AP15) -> 0 | AR15: =AQ15/AQ23 -> #DIV/0! | AS15: =+K15+S15+AA15+AI15+AQ15 -> 35 | AT15: =AS15/AS23 -> 0.010315355
C16: Total | D16: =SUM(D13:D15) -> 0.5 | E16: =SUM(E13:E15) -> 2 | F16: =SUM(F13:F15) -> 20 | G16: =SUM(G13:G15) -> 2.5 | H16: =SUM(H13:H15) -> 6 | I16: =SUM(I13:I15) -> 5 | J16: =SUM(J13:J15) -> 0 | K16: =SUM(D16:J16) -> 36 | L16: =K16/K23 -> 0.023285899 | M16: =SUM(M13:M15) -> 1.5 | N16: =SUM(N13:N15) -> 3.5 | O16: =SUM(O13:O15) -> 11.5 | P16: =SUM(P13:P15) -> 4.5 | Q16: =SUM(Q13:Q15) -> 0 | R16: =SUM(R13:R15) -> 0 | S16: =SUM(M16:R16) -> 21 | T16: =S16/S23 -> 0.011369789 | U16: =SUM(U13:U15) -> 0 | V16: =SUM(V13:V15) -> 0 | W16: =SUM(W13:W15) -> 0 | X16: =SUM(X13:X15) -> 0 | Y16: =SUM(Y13:Y15) -> 0 | Z16: =SUM(Z13:Z15) -> 0 | AA16: =SUM(U16:Z16) -> 0 | AB16: =AA16/AA23 -> #DIV/0! | AC16: =SUM(AC13:AC15) -> 0 | AD16: =SUM(AD13:AD15) -> 0 | AE16: =SUM(AE13:AE15) -> 0 | AF16: =SUM(AF13:AF15) -> 0 | AG16: =SUM(AG13:AG15) -> 0 | AH16: =SUM(AH13:AH15) -> 0 | AI16: =SUM(AC16:AH16) -> 0 | AJ16: =AI16/AI23 -> #DIV/0! | AK16: =SUM(AK13:AK15) -> 0 | AL16: =SUM(AL13:AL15) -> 0 | AM16: =SUM(AM13:AM15) -> 0 | AN16: =SUM(AN13:AN15) -> 0 | AO16: =SUM(AO13:AO15) -> 0 | AP16: =SUM(AP13:AP15) -> 0 | AQ16: =SUM(AK16:AP16) -> 0 | AR16: =AQ16/AQ23 -> #DIV/0! | AS16: =+K16+S16+AA16+AI16+AQ16 -> 57 | AT16: =AS16/AS23 -> 0.016799293
B17: A-Grade | C17: Line- | D17: 0 | E17: 0 | F17: 0 | G17: 0 | H17: 0 | I17: 0 | J17: 0 | K17: =SUM(D17:J17) -> 0 | L17: =K17/K23 -> 0 | M17: 0 | N17: 0 | O17: 0 | P17: 0 | Q17: 0 | R17: 0 | S17: =SUM(M17:R17) -> 0 | T17: =S17/S23 -> 0 | U17: 0 | V17: 0 | W17: 0 | X17: 0 | Y17: 0 | Z17: 0 | AA17: =SUM(U17:Z17) -> 0 | AB17: =AA17/AA23 -> #DIV/0! | AC17: 0 | AD17: 0 | AE17: 0 | AF17: 0 | AG17: 0 | AH17: 0 | AI17: =SUM(AC17:AH17) -> 0 | AJ17: =AI17/AI23 -> #DIV/0! | AK17: 0 | AL17: 0 | AM17: 0 | AN17: 0 | AO17: 0 | AP17: 0 | AQ17: =SUM(AK17:AP17) -> 0 | AR17: =AQ17/AQ23 -> #DIV/0! | AS17: =+K17+S17+AA17+AI17+AQ17 -> 0 | AT17: =AS17/AS23 -> 0
C18: Line 6 | D18: 0 | E18: 90 | F18: 290 | G18: 460 | H18: 330 | I18: 340 | J18: 0 | K18: =SUM(D18:J18) -> 1510 | L18: =K18/K23 -> 0.9767141 | M18: 310 | N18: 380 | O18: 776 | P18: 360 | Q18: 0 | R18: 0 | S18: =SUM(M18:R18) -> 1826 | T18: =S18/S23 -> 0.98863021 | U18: 0 | V18: 0 | W18: 0 | X18: 0 | Y18: 0 | Z18: 0 | AA18: =SUM(U18:Z18) -> 0 | AB18: =AA18/AA23 -> #DIV/0! | AC18: 0 | AD18: 0 | AE18: 0 | AF18: 0 | AG18: 0 | AH18: 0 | AI18: =SUM(AC18:AH18) -> 0 | AJ18: =AI18/AI23 -> #DIV/0! | AK18: 0 | AL18: 0 | AM18: 0 | AN18: 0 | AO18: 0 | AP18: 0 | AQ18: =SUM(AK18:AP18) -> 0 | AR18: =AQ18/AQ23 -> #DIV/0! | AS18: =+K18+S18+AA18+AI18+AQ18 -> 3336 | AT18: =AS18/AS23 -> 0.98320071
D19: 0 | E19: 0 | F19: 0 | G19: 0 | H19: 0 | I19: 0 | J19: 0 | K19: =SUM(D19:J19) -> 0 | L19: =K19/K23 -> 0 | M19: 0 | N19: 0 | O19: 0 | P19: 0 | Q19: 0 | R19: 0 | S19: =SUM(M19:R19) -> 0 | T19: =S19/S23 -> 0 | U19: 0 | V19: 0 | W19: 0 | X19: 0 | Y19: 0 | Z19: 0 | AA19: =SUM(U19:Z19) -> 0 | AB19: =AA19/AA23 -> #DIV/0! | AC19: 0 | AD19: 0 | AE19: 0 | AF19: 0 | AG19: 0 | AH19: 0 | AI19: =SUM(AC19:AH19) -> 0 | AJ19: =AI19/AI23 -> #DIV/0! | AK19: 0 | AL19: 0 | AM19: 0 | AN19: 0 | AO19: 0 | AP19: 0 | AQ19: =SUM(AK19:AP19) -> 0 | AR19: =AQ19/AQ23 -> #DIV/0! | AS19: =+K19+S19+AA19+AI19+AQ19 -> 0 | AT19: =AS19/AS23 -> 0
B20: Total | D20: =SUM(D17:D19) -> 0 | E20: =SUM(E17:E19) -> 90 | F20: =SUM(F17:F19) -> 290 | G20: =SUM(G17:G19) -> 460 | H20: =SUM(H17:H19) -> 330 | I20: =SUM(I17:I19) -> 340 | J20: =SUM(J17:J19) -> 0 | K20: =SUM(D20:J20) -> 1510 | L20: =K20/K23 -> 0.9767141 | M20: =SUM(M17:M19) -> 310 | N20: =SUM(N17:N19) -> 380 | O20: =SUM(O17:O19) -> 776 | P20: =SUM(P17:P19) -> 360 | Q20: =SUM(Q17:Q19) -> 0 | R20: =SUM(R17:R19) -> 0 | S20: =SUM(M20:R20) -> 1826 | T20: =S20/S23 -> 0.98863021 | U20: =SUM(U17:U19) -> 0 | V20: =SUM(V17:V19) -> 0 | W20: =SUM(W17:W19) -> 0 | X20: =SUM(X17:X19) -> 0 | Y20: =SUM(Y17:Y19) -> 0 | Z20: =SUM(Z17:Z19) -> 0 | AA20: =SUM(U20:Z20) -> 0 | AB20: =AA20/AA23 -> #DIV/0! | AC20: =SUM(AC17:AC19) -> 0 | AD20: =SUM(AD17:AD19) -> 0 | AE20: =SUM(AE17:AE19) -> 0 | AF20: =SUM(AF17:AF19) -> 0 | AG20: =SUM(AG17:AG19) -> 0 | AH20: =SUM(AH17:AH19) -> 0 | AI20: =SUM(AC20:AH20) -> 0 | AJ20: =AI20/AI23 -> #DIV/0! | AK20: =SUM(AK17:AK19) -> 0 | AL20: =SUM(AL17:AL19) -> 0 | AM20: =SUM(AM17:AM19) -> 0 | AN20: =SUM(AN17:AN19) -> 0 | AO20: =SUM(AO17:AO19) -> 0 | AP20: =SUM(AP17:AP19) -> 0 | AQ20: =SUM(AK20:AP20) -> 0 | AR20: =AQ20/AQ23 -> #DIV/0! | AS20: =+K20+S20+AA20+AI20+AQ20 -> 3336 | AT20: =AS20/AS23 -> 0.98320071
I22: TOT. DOD | K22: =+K8+K12+K16 -> 36 | L22: =K22/K23 -> 0.023285899 | Q22: TOT.BC | S22: =+S8+S12+S16 -> 21 | T22: =S22/S23 -> 0.011369789 | Y22: TOT. BC | AA22: =+AA8+AA12+AA16 -> 0 | AB22: =AA22/AA23 -> #DIV/0! | AG22: TOT. BC | AI22: =+AI8+AI12+AI16 -> 0 | AJ22: =AI22/AI23 -> #DIV/0! | AO22: TOT. DOD | AQ22: =+AQ8+AQ12+AQ16 -> 0 | AR22: =AQ22/AQ23 -> #DIV/0! | AS22: =+AS8+AS12+AS16 -> 57 | AT22: =+AT8+AT12+AT16 -> 0.016799293 | AU22: =AT12+AT16 -> 0.016799293
I23: TOT. PROD | K23: =+K22+K20 -> 1546 | Q23: TOT. PROD | S23: =+S22+S20 -> 1847 | Y23: TOT. PROD | AA23: =+AA22+AA20 -> 0 | AG23: TOT. PROD | AI23: =+AI22+AI20 -> 0 | AO23: TOT. PROD | AQ23: =+AQ22+AQ20 -> 0 | AS23: =+AS22+AS20 -> 3393

Sheet B.Grade
B2: B.GRADE OFF WHITE
B4: WEEK | C4: DATE | D4: LINE | E4: MODEL NAME | F4: COLORS | G4: SIZE | H4: Pitting | I4: Blister Tech | J4: Blister Assy | K4: Stroble | L4: Over Buffing | M4: Over Cement | N4: Shapping | O4: Lining | P4: Bubble | Q4: Dam. Vamp | R4: Dam. Foxing | S4: Dam. Upper | T4: Dam. Spray | U4: Dam.O/S | V4: Dam. Leg | W4: X. Lining | X4: X. Vamp | Y4: X. Process | Z4: Others | AA4: Total | AB4: Total Per-hari
B5: Week#1 | AA5: =SUM(H5:Y5) -> 0 | AB5: =SUM(AA5:AA6) -> 0
B6: Week#1 | AA6: =SUM(H6:Y6) -> 0
B7: Week#1 | AA7: =SUM(H7:Y7) -> 0
B8: Week#1 | AA8: =SUM(H8:Y8) -> 0 | AB8: =SUM(AA8:AA9) -> 0
B9: Week#1 | AA9: =SUM(H9:Y9) -> 0
B10: Week#1 | AA10: =SUM(H10:Y10) -> 0 | AB10: =SUM(AA10:AA11) -> 0
B11: Week#1 | AA11: =SUM(H11:Y11) -> 0
B12: Week#1 | AA12: =SUM(H12:Y12) -> 0
B13: Week#1 | AA13: =SUM(H13:Y13) -> 0
B14: Week#1 | AA14: =SUM(H14:Y14) -> 0 | AB14: =SUM(AA14:AA15) -> 0
B15: Week#1 | AA15: =SUM(H15:Y15) -> 0
B16: Week#1 | AA16: =SUM(H16:Y16) -> 0 | AB16: =AA16 -> 0
B17: Week#1 | AA17: =SUM(H17:Y17) -> 0 | AB17: =SUM(AA17:AA19) -> 0
B18: Week#1 | AA18: =SUM(H18:Y18) -> 0
B19: Week#1 | AA19: =SUM(H19:Y19) -> 0
B20: Week#1 | AA20: =SUM(H20:Y20) -> 0
B21: Week#1 | AA21: =SUM(H21:Y21) -> 0
B22: Week#1 | AA22: =SUM(H22:Y22) -> 0
B23: Week#1 | AA23: =SUM(H23:Y23) -> 0 | AB23: =SUM(AA23:AA37) -> 0
B24: Week#1 | AA24: =SUM(H24:Z24) -> 0
B25: Week#1 | AA25: =SUM(H25:Z25) -> 0
B26: Week#1 | AA26: =SUM(H26:Z26) -> 0
B27: Week#1 | AA27: =SUM(H27:Z27) -> 0
B28: Week#1 | AA28: =SUM(H28:Z28) -> 0
B29: Week#1 | AA29: =SUM(H29:Z29) -> 0
B30: Week#1 | AA30: =SUM(H30:Z30) -> 0
B31: Week#1 | AA31: =SUM(H31:Z31) -> 0
B32: Week#1 | AA32: =SUM(H32:Z32) -> 0
B33: Week#1 | AA33: =SUM(H33:Z33) -> 0
B34: Week#1 | AA34: =SUM(H34:Z34) -> 0
B35: Week#1 | AA35: =SUM(H35:Z35) -> 0
... B37: Week#1 | AA37: =SUM(H37:Z37) -> 0
B38: Week#1 | AA38: =SUM(H38:Z38) -> 0 | AB38: =SUM(AA38:AA47) -> 0
B39: Week#1 | AA39: =SUM(H39:Z39) -> 0
B40: Week#1 | AA40: =SUM(H40:Z40) -> 0
B41: Week#1 | AA41: =SUM(H41:Z41) -> 0
B42: Week#1 | AA42: =SUM(H42:Z42) -> 0
B43: Week#1 | AA43: =SUM(H43:Z43) -> 0
...

Sheet DONATION
B2: DONATION
B4: WEEK | C4: DATE | D4: LINE | E4: MODEL NAME | F4: COLORS | G4: SIZE | H4: Pitting | I4: Blister Tech | J4: Blister Assy | K4: Pin Hole | L4: Indent | M4: Shapping | N4: Lining | O4: Bubble | P4: Dam. Vamp | Q4: Dam. Foxing | R4: Dam. H/S | S4: Dam. Spray | T4: Dam. Leg | U4: Dam. Top Bind | V4: Dam. Logo | W4: X. Lining | X4: X. Vamp | Y4: X. Process | Z4: Contamination | AA4: Orange Peel | AB4: Trimming | AC4: Bond gap vamp | AD4: Bond Gap Outsole | AE4: Bond gap Lining | AF4: Gusset | AG4: Over Buffing | AH4: Over Cement | AI4: Others | AJ4: Total | AK4: Total Per-hari
B5: Week#1 | AJ5: =SUM(H5:AI5) -> 0 | AK5: =SUM(AJ5:AJ9) -> 0
B6: Week#1 | AJ6: =SUM(H6:AI6) -> 0
B7: Week#1 | AJ7: =SUM(H7:AI7) -> 0
B8: Week#1 | AJ8: =SUM(H8:AI8) -> 0
B9: Week#1 | AJ9: =SUM(H9:AI9) -> 0
B10: Week#1 | AJ10: =SUM(H10:AI10) -> 0 | AK10: =SUM(AJ10:AJ16) -> 0
B11: Week#1 | AJ11: =SUM(H11:AI11) -> 0
B12: Week#1 | AJ12: =SUM(H12:AI12) -> 0
B13: Week#1 | AJ13: =SUM(H13:AI13) -> 0
B14: Week#1 | AJ14: =SUM(H14:AI14) -> 0
B15: Week#1 | AJ15: =SUM(H15:AI15) -> 0
B16: Week#1 | AJ16: =SUM(H16:AI16) -> 0
B17: Week#1 | AJ17: =SUM(H17:AI17) -> 0 | AK17: =SUM(AJ17:AJ21) -> 0
B18: Week#1 | AJ18: =SUM(H18:AI18) -> 0
B19: Week#1 | AJ19: =SUM(H19:AI19) -> 0
B20: Week#1 | AJ20: =SUM(H20:AI20) -> 0
B21: Week#1 | AJ21: =SUM(H21:AI21) -> 0
B22: Week#1 | AJ22: =SUM(H22:AI22) -> 0 | AK22: =SUM(AJ22:AJ27) -> 0
B23: Week#1 | AJ23: =SUM(H23:AI23) -> 0
B24: Week#1 | AJ24: =SUM(H24:AI24) -> 0
B25: Week#1 | AJ25: =SUM(H25:AI25) -> 0
B26: Week#1 | AJ26: =SUM(H26:AI26) -> 0
B27: Week#1 | AJ27: =SUM(H27:AI27) -> 0
B28: Week#1 | AJ28: =SUM(H28:AI28) -> 0 | AK28: =SUM(AJ28:AJ30) -> 0
B29: Week#1 | AJ29: =SUM(H29:AI29) -> 0
B30: Week#1 | AJ30: =SUM(H30:AI30) -> 0
B31: Week#1 | AJ31: =SUM(H31:AI31) -> 0 | AK31: =SUM(AJ31:AJ34) -> 0
B32: Week#1 | AJ32: =SUM(H32:AI32) -> 0
B33: Week#1 | AJ33: =SUM(H33:AI33) -> 0
B34: Week#1 | AJ34: =SUM(H34:AI34) -> 0
B35: Week#1 | AJ35: =SUM(H35:AI35) -> 0
B36: Week#1 | AJ36: =SUM(H36:AI36) -> 0
B37: Week#1 | AJ37: =SUM(H37:AI37) -> 0
B38: Week#1 | AJ38: =SUM(H38:AI38) -> 0
B39: Week#1 | AJ39: =SUM(H39:AI39) -> 0
B40: Week#1 | AJ40: =SUM(H40:AI40) -> 0
B41: Week#1 | AJ41: =SUM(H41:AI41) -> 0
B42: Week#1 | AJ42: =SUM(H42:AI42) -> 0
...

Sheet C.Grade
B2: C GRADE OFF WHITE
B4: WEEK | C4: DATE | D4: LINE | E4: CODE | F4: MODEL NAME | G4: COLORS | H4: SIZE | I4: Pitting | J4: Blister Tech | K4: Blister Assy | L4: Pin Hole | M4: Indent | N4: Shapping | O4: Lining | P4: Bubble | Q4: Dam. Lining | R4: Dam. Foxing | S4: Dam. Upper | T4: Dam. Spray | U4: Dam. O/S | V4: Dam. Leg | W4: Dam. Lining | X4: Dam. Top Bind | Y4: Dam. Logo | Z4: X. Lining | AA4: X. Vamp | AB4: X. Process | AC4: Contamination | AD4: Orange Peel | AE4: Trimming | AF4: Bond gap vamp | AG4: Bond Gap Outsole | AH4: Bond gap Lining | AI4: Gusset | AJ4: Salah Buckle | AK4: Salah Gauge | AL4: Yellowing | AM4: Uncure | AN4: Others | AO4: Total | AP4: Total Per-hari
B5: Week#1 | C5: 44743 | D5: 6 | E5: PWIE004F22MAT001 | F5: Sponge Rubber Rain | G5: White | H5: 40 | K5: 0.5 | AO5: =SUM(I5:AN5) -> 0.5 | AP5: 0.5 | AR5: Cold Cement
B6: Week#1 | C6: 44746 | D6: 6 | E6: PWIE004F22MAT001 | F6: Sponge Rubber Rain | G6: White | H6: 37 | P6: 0.5 | AO6: =SUM(I6:AN6) -> 0.5 | AP6: =SUM(AO6:AO8) -> 2
B7: Week#1 | C7: 44746 | D7: 6 | E7: PWIE004F22MAT001 | F7: Sponge Rubber Rain | G7: White | H7: 38 | P7: 0.5 | AO7: =SUM(I7:AN7) -> 0.5
B8: Week#1 | C8: 44746 | D8: 6 | E8: PWIE004F22MAT001 | F8: Sponge Rubber Rain | G8: White | H8: 39 | Q8: 1 | AO8: =SUM(I8:AN8) -> 1
B9: Week#1 | C9: 44747 | D9: 6 | E9: PWIE004F22MAT001 | F9: Sponge Rubber Rain | G9: White | H9: 36 | Q9: 0.5 | AO9: =SUM(I9:AN9) -> 0.5 | AP9: =SUM(AO9:AO20) -> 20
B10: Week#1 | C10: 44747 | D10: 6 | E10: PWIE004F22MAT001 | F10: Sponge Rubber Rain | G10: White | H10: 37 | U10: 0.5 | AO10: =SUM(I10:AN10) -> 0.5
B11: Week#1 | C11: 44747 | D11: 6 | E11: PWIE004F22MAT001 | F11: Sponge Rubber Rain | G11: White | H11: 38 | U11: 0.5 | AO11: =SUM(I11:AN11) -> 0.5
B12: Week#1 | C12: 44747 | D12: 6 | E12: PWIE004F22MAT001 | F12: Sponge Rubber Rain | G12: White | H12: 39 | Q12: 0.5 | AO12: =SUM(I12:AN12) -> 0.5
B13: Week#1 | C13: 44747 | D13: 6 | E13: PWIE004F22MAT001 | F13: Sponge Rubber Rain | G13: Black | H13: 36 | K13: 0.5 | AC13: 3 | AO13: =SUM(I13:AN13) -> 3.5 | AR13: Cold Cement
B14: Week#1 | C14: 44747 | D14: 6 | E14: PWIE004F22MAT001 | F14: Sponge Rubber Rain | G14: Black | H14: 37 | I14: 0.5 | AC14: 1.5 | AO14: =SUM(I14:AN14) -> 2 | AR14: Cold Cement
B15: Week#1 | C15: 44747 | D15: 6 | E15: PWIE004F22MAT001 | F15: Sponge Rubber Rain | G15: Black | H15: 38 | AC15: 2.5 | AO15: =SUM(I15:AN15) -> 2.5 | AR15: Cold Cement
B16: Week#1 | C16: 44747 | D16: 6 | E16: PWIE004F22MAT001 | F16: Sponge Rubber Rain | G16: Black | H16: 39 | AC16: 6 | AO16: =SUM(I16:AN16) -> 6 | AR16: Cold Cement
B17: Week#1 | C17: 44747 | D17: 6 | E17: PWIE004F22MAT001 | F17: Sponge Rubber Rain | G17: Black | H17: 40 | AC17: 1.5 | AO17: =SUM(I17:AN17) -> 1.5 | AR17: Cold Cement
B18: Week#1 | C18: 44747 | D18: 6 | E18: PWIE004F22MAT001 | F18: Sponge Rubber Rain | G18: Black | H18: 41 | AC18: 1 | AO18: =SUM(I18:AN18) -> 1 | AR18: Cold Cement
B19: Week#1 | C19: 44747 | D19: 6 | E19: PWIE004F22MAT001 | F19: Sponge Rubber Rain | G19: Black | H19: 42 | AC19: 1 | AO19: =SUM(I19:AN19) -> 1 | AR19: Cold Cement
B20: Week#1 | C20: 44747 | D20: 6 | E20: PWIE004F22MAT001 | F20: Sponge Rubber Rain | G20: White | H20: 37 | I20: 0.5 | AO20: =SUM(I20:AN20) -> 0.5 | AR20: Cold Cement
B21: Week#1 | C21: 44748 | D21: 6 | E21: PWIE004F22MAT001 | F21: Sponge Rubber Rain | G21: White | H21: 38 | Q21: 0.5 | AO21: =SUM(I21:AN21) -> 0.5 | AP21: =SUM(AO21:AO24) -> 2.5
B22: Week#1 | C22: 44748 | D22: 6 | E22: PWIE004F22MAT001 | F22: Sponge Rubber Rain | G22: White | H22: 41 | M22: 0.5 | AO22: =SUM(I22:AN22) -> 0.5 | AR22: Cold Cement
B23: Week#1 | C23: 44748 | D23: 6 | E23: OWIE016F22MAT001 | F23: Sponge Rubber Rain | G23: Pink purple | H23: 37 | S23: 0.5 | AO23: =SUM(I23:AN23) -> 0.5 | AR23: Cold Cement
B24: Week#1 | C24: 44748 | D24: 6 | E24: OWIE016F22MAT001 | F24: Sponge Rubber Rain | G24: Pink purple | H24: 38 | I24: 1 | AO24: =SUM(I24:AN24) -> 1 | AR24: Cold Cement
B25: Week#1 | C25: 44749 | D25: 6 | E25: PWIE004F22MAT001 | F25: Sponge Rubber Rain | G25: Black | H25: 38 | P25: 1 | AO25: =SUM(I25:AN25) -> 1 | AP25: =SUM(AO25:AO30) -> 6
B26: Week#1 | C26: 44749 | D26: 6 | E26: PWIE004F22MAT001 | F26: Sponge Rubber Rain | G26: Black | H26: 36 | AB26: 0.5 | AO26: =SUM(I26:AN26) -> 0.5 | AR26: Cold Cement
B27: Week#1 | C27: 44749 | D27: 6 | E27: PWIE004F22MAT001 | F27: Sponge Rubber Rain | G27: Black | H27: 37 | I27: 1 | S27: 0.5 | AO27: =SUM(I27:AN27) -> 1.5 | AR27: Cold Cement
B28: Week#1 | C28: 44749 | D28: 6 | E28: PWIE004F22MAT001 | F28: Sponge Rubber Rain | G28: Black | H28: 38 | P28: 0.5 | AB28: 0.5 | AO28: =SUM(I28:AN28) -> 1 | AR28: Cold Cement
B29: Week#1 | C29: 44749 | D29: 6 | E29: PWIE004F22MAT001 | F29: Sponge Rubber Rain | G29: Black | H29: 39 | P29: 1.5 | AO29: =SUM(I29:AN29) -> 1.5 | AR29: Cold Cement
B30: Week#1 | C30: 44749 | D30: 6 | E30: OWIE016F22MAT001 | F30: Sponge Rubber Rain | G30: Pink purple | H30: 41 | M30: 0.5 | AO30: =SUM(I30:AN30) -> 0.5 | AR30: Cold Cement
B31: Week#1 | C31: 44750 | D31: 6 | E31: PWIE004F22MAT001 | F31: Sponge Rubber Rain | G31: Black | H31: 38 | P31: 2.5 | AO31: =SUM(I31:AN31) -> 2.5 | AP31: =SUM(AO31:AO35) -> 5
B32: Week#1 | C32: 44750 | D32: 6 | E32: PWIE004F22MAT001 | F32: Sponge Rubber Rain | G32: Black | H32: 39 | P32: 0.5 | AO32: =SUM(I32:AN32) -> 0.5
B33: Week#1 | C33: 44750 | D33: 6 | E33: PWIE004F22MAT001 | F33: Sponge Rubber Rain | G33: Black | H33: 35 | AB33: 0.5 | AO33: =SUM(I33:AN33) -> 0.5 | AR33: Cold Cement
B34: Week#1 | C34: 44750 | D34: 6 | E34: PWIE004F22MAT001 | F34: Sponge Rubber Rain | G34: Black | H34: 36 | I34: 0.5 | K34: 0.5 | AO34: =SUM(I34:AN34) -> 1 | AR34: Cold Cement
B35: Week#1 | C35: 44750 | D35: 6 | E35: PWIE004F22MAT001 | F35: Sponge Rubber Rain | G35: Black | H35: 38 | P35: 0.5 | AO35: =SUM(I35:AN35) -> 0.5 | AR35: Cold Cement
B36: Week#1 | AO36: =SUM(I36:AN36) -> 0
B37: Week#1 | AO37: =SUM(I37:AN37) -> 0
B38: Week#1 | AO38: =SUM(I38:AN38) -> 0
B39: Week#1 | AO39: =SUM(I39:AN39) -> 0 | AP39: =SUM(AO39:AO76) -> 0
B40: Week#1 | AO40: =SUM(I40:AN40) -> 0
B41: Week#1 | AO41: =SUM(I41:AN41) -> 0
B42: Week#1 | AO42: =SUM(I42:AN42) -> 0
...

Sheet Summary DOD by Issue
C2: SUMMARY DOD by DEFECT
D4: Pitting | E4: Blister Tech | F4: Blister Assy | G4: Stroble | H4: Indent | I4: Shapping | J4: Lining | K4: Bubble | L4: Dam. Vamp | M4: Dam. Foxing | N4: Dam. H/S | O4: Dam. Spray | P4: Dam. O/S | Q4: Dam. Leg | R4: Dam. Lining | S4: Dam. Top Bind | T4: Dam. Logo | U4: X. Lining | V4: X. Vamp | W4: X. Process | X4: Contamination | Y4: Orange Peel | Z4: Trimming | AA4: Bond gap vamp | AB4: Bond Gap Outsole | AC4: Bond gap Lining | AD4: Gusset | AE4: Salah Buckle | AF4: Salah Gauge | AG4: Re Bonding | AH4: Uncure | AI4: Over Buffing | AJ4: Over Cement | AK4: Others | AL4: TOTAL
B5: Week 1 | C5: Outlet | D5: =B.Grade!H52 -> 0 | E5: =B.Grade!I52 -> 0 | F5: =B.Grade!J52 -> 0 | G5: =B.Grade!K52 -> 0 | H5: =B.Grade!L52 -> 0 | I5: =B.Grade!N52 -> 0 | J5: =B.Grade!O52 -> 0 | K5: =B.Grade!P52 -> 0 | L5: =B.Grade!Q52 -> 0 | M5: =B.Grade!R52 -> 0 | N5: =B.Grade!S52 -> 0 | O5: =B.Grade!T52 -> 0 | P5: =B.Grade!U52 -> 0 | Q5: =B.Grade!V52 -> 0 | S5: =B.Grade!X52 -> 0 | T5: =B.Grade!Y52 -> 0 | U5: =B.Grade!W52 -> 0 | V5: =B.Grade!X52 -> 0 | W5: =B.Grade!Y52 -> 0 | X5: =B.Grade!Z52 -> 0 | AJ5: =B.Grade!M52 -> 0 | AK5: =B.Grade!Z52 -> 0 | AL5: =SUM(D5:AK5) -> 0
C6: Donation | D6: =DONATION!H79 -> 0 | E6: =DONATION!I79 -> 0 | F6: =DONATION!J79 -> 0 | G6: =DONATION!K79 -> 0 | H6: =DONATION!L79 -> 0 | I6: =DONATION!M79 -> 0 | J6: =DONATION!N79 -> 0 | K6: =DONATION!O79 -> 0 | ... P6: =DONATION!T79 -> 0 | Q6: =DONATION!T79 -> 0 | R6: =DONATION!U79 -> 0 | S6: =DONATION!U79 -> 0 | T6: =DONATION!V79 -> 0 | U6: =DONATION!W79 -> 0 | V6: =DONATION!X79 -> 0 | W6: =DONATION!Y79 -> 0 | X6: =DONATION!Z79 -> 0 | Y6: =DONATION!AA79 -> 0 | Z6: =DONATION!AB79 -> 0 | ... AD6: =DONATION!AF79 -> 0 | AI6: =DONATION!AG79 -> 0 | AJ6: =DONATION!AH79 -> 0 | AK6: =DONATION!AI79 -> 0 | AL6: =SUM(D6:AK6) -> 0
C7: Destroy | D7: ='C.Grade'!I223 -> 3.5 | E7: ='C.Grade'!J223 -> 0 | F7: ='C.Grade'!K223 -> 1.5 | G7: ='C.Grade'!L223 -> 0 | H7: ='C.Grade'!M223 -> 1 | I7: ='C.Grade'!N223 -> 0 | J7: ='C.Grade'!O223 -> 0 | K7: ='C.Grade'!P223 -> 7.5 | ... AH7: ='C.Grade'!AM223 -> 0 | AK7: ='C.Grade'!AN223 -> 0 | AL7: =SUM(D7:AK7) -> 36
C8: Total | D8: =SUM(D5:D7) -> 3.5 | E8: =SUM(E5:E7) -> 0 | F8: =SUM(F5:F7) -> 1.5 | G8: =SUM(G5:G7) -> 0 | H8: =SUM(H5:H7) -> 1 | I8: =SUM(I5:I7) -> 0 | J8: =SUM(J5:J7) -> 0 | K8: =SUM(K5:K7) -> 7.5 | ... AL8: =SUM(AL5:AL7) -> 36
C9: Total | D9: =D8 -> 3.5 | E9: =+E8+F8 -> 1.5 | G9: =G8 -> 0 | H9: =H8 -> 1 | I9: =I8 -> 0 | J9: =J8 -> 0 | K9: =K8 -> 7.5 | L9: =+L8+M8+N8+O8+P8+Q8+R8+S8+T8 -> 4.5 | U9: =+U8+V8+W8 -> 1.5 | X9: =X8 -> 16.5 | Y9: =Y8 -> 0 | Z9: =Z8 -> 0 | AA9: =+AA8+AB8+AC8 -> 0 | AD9: =AD8 -> 0 | AE9: =AE8 -> 0 | AF9: =AF8 -> 0 | AG9: =AG8 -> 0 | AH9: =AH8 -> 0 | AI9: =AI8 -> 0 | AJ9: =AJ8 -> 0 | AK9: =AK8 -> 0 | AL9: =AL8 -> 36
B10: Week 2 | C10: Outlet | D10: =B.Grade!H124 -> 0 | E10: =B.Grade!I124 -> 0 | F10: =B.Grade!J124 -> 0 | G10: =B.Grade!K124 -> 0 | I10: =B.Grade!N124 -> 0 | J10: =B.Grade!O124 -> 0 | K10: =B.Grade!P124 -> 0 | L10: =B.Grade!Q124 -> 0 | M10: =B.Grade!R124 -> 0 | N10: =B.Grade!S124 -> 0 | O10: =B.Grade!T124 -> 0 | Q10: =B.Grade!V124 -> 0 | U10: =B.Grade!W124 -> 0 | V10: =B.Grade!X124 -> 0 | W10: =B.Grade!Y124 -> 0 | AI10: =B.Grade!L124 -> 0 | AJ10: =B.Grade!M124 -> 0 | AK10: =B.Grade!Z124 -> 0 | AL10: =SUM(D10:AK10) -> 0
C11: Donation | D11: =DONATION!H187 -> 0 | E11: =DONATION!I187 -> 0 | F11: =DONATION!J187 -> 0 | G11: =DONATION!K187 -> 0 | H11: =DONATION!L187 -> 0 | I11: =DONATION!M187 -> 0 | J11: =DONATION!N187 -> 0 | K11: =DONATION!O187 -> 0 | ... P11: =DONATION!T187 -> 0 | Q11: =DONATION!T187 -> 0 | R11: =DONATION!U187 -> 0 | S11: =DONATION!U187 -> 0 | T11: =DONATION!V187 -> 0 | U11: =DONATION!W187 -> 0 | V11: =DONATION!X187 -> 0 | W11: =DONATION!Y187 -> 0 | X11: =DONATION!Z187 -> 0 | Y11: =DONATION!AA187 -> 0 | Z11: =DONATION!AB187 -> 0 | ... AD11: =DONATION!AF187 -> 0 | AE11: =DONATION!AI187 -> 0 | AI11: =DONATION!AG187 -> 0 | AJ11: =DONATION!AH187 -> 0 | AK11: =DONATION!AI187 -> 0 | AL11: =SUM(D11:AK11) -> 0
C12: Destroy | D12: ='C.Grade'!I427 -> 0 | E12: ='C.Grade'!J427 -> 0 | F12: ='C.Grade'!K427 -> 0.5 | G12: ='C.Grade'!L427 -> 0 | H12: ='C.Grade'!M427 -> 0 | I12: ='C.Grade'!N427 -> 0 | J12: ='C.Grade'!O427 -> 11 | K12: ='C.Grade'!P427 -> 2 | ... AH12: ='C.Grade'!AM427 -> 0 | AK12: ='C.Grade'!AN427 -> 0 | AL12: =SUM(D12:AK12) -> 21
C13: Total | D13: =SUM(D10:D12) -> 0 | E13: =SUM(E10:E12) -> 0 | F13: =SUM(F10:F12) -> 0.5 | G13: =SUM(G10:G12) -> 0 | H13: =SUM(H10:H12) -> 0 | I13: =SUM(I10:I12) -> 0 | J13: =SUM(J10:J12) -> 11 | K13: =SUM(K10:K12) -> 2 | ... O13: =SUM(O10:O12) -> 0 | Q13: =SUM(Q10:Q12) -> 0 | S13: =SUM(S10:S12) -> 0 | T13: =SUM(T10:T12) -> 0 | U13: =SUM(U10:U12) -> 0 | V13: =SUM(V10:V12) -> 0 | W13: =SUM(W10:W12) -> 3.5 | X13: =SUM(X10:X12) -> 0 | Y13: =SUM(Y10:Y12) -> 0 | Z13: =SUM(Z10:Z12) -> 0 | ... AL13: =SUM(AL10:AL12) -> 21
C14: Total | D14: =D13 -> 0 | E14: =+E13+F13 -> 0.5 | G14: =G13 -> 0 | H14: =H13 -> 0 | I14: =I13 -> 0 | J14: =J13 -> 11 | K14: =K13 -> 2 | L14: =+L13+M13+N13+O13+Q13+S13+T13 -> 3 | U14: =+U13+V13+W13 -> 3.5 | X14: =X13 -> 0 | Y14: =Y13 -> 0 | Z14: =Z13 -> 0 | AA14: =+AA13+AB13+AC13 -> 0 | AD14: =AD13 -> 0 | AE14: =AE13 -> 0 | AF14: =AF13 -> 0 | AG14: =AG13 -> 0 | AH14: =AH13 -> 0 | AI14: =AI13 -> 0 | AJ14: =AJ13 -> 0 | AK14: =AK13 -> 0 | AL14: =AL13 -> 21
B15: Week 3 | C15: Outlet | D15: =B.Grade!H164 -> 0 | E15: =B.Grade!I164 -> 0 | F15: =B.Grade!J164 -> 0 | G15: =B.Grade!K164 -> 0 | H15: =B.Grade!L164 -> 0 | I15: =B.Grade!N164 -> 0 | J15: =B.Grade!O164 -> 0 | K15: =B.Grade!P164 -> 0 | L15: =B.Grade!Q164 -> 0 | M15: =B.Grade!R164 -> 0 | N15: =B.Grade!S164 -> 0 | O15: =B.Grade!T164 -> 0 | Q15: =B.Grade!V164 -> 0 | U15: =B.Grade!W164 -> 0 | V15: =B.Grade!X164 -> 0 | W15: =B.Grade!Y164 -> 0 | AK15: =B.Grade!Z164 -> 0 | AL15: =SUM(D15:AK15) -> 0
C16: Donation | D16: =DONATION!H348 -> 0 | E16: =DONATION!I348 -> 0 | F16: =DONATION!J348 -> 0 | G16: =DONATION!K348 -> 0 | H16: =DONATION!L348 -> 0 | I16: =DONATION!M348 -> 0 | J16: =DONATION!N348 -> 0 | K16: =DONATION!O348 -> 0 | ... O16: =DONATION!S348 -> 0 | Q16: =DONATION!T348 -> 0 | R16: =DONATION!V348 -> 0 | S16: =DONATION!W348 -> 0 | T16: =DONATION!X348 -> 0 | U16: =DONATION!Y348 -> 0 | V16: =DONATION!Z348 -> 0 | W16: =DONATION!AA348 -> 0 | X16: =DONATION!AB348 -> 0 | Y16: =DONATION!AC348 -> 0 | Z16: =DONATION!AB348 -> 0 | AA16: =DONATION!AC348 -> 0 | AB16: =DONATION!AD348 -> 0 | AC16: =DONATION!AE348 -> 0 | AD16: =DONATION!AF348 -> 0 | AI16: =DONATION!AG348 -> 0 | AJ16: =DONATION!AH348 -> 0 | AK16: =DONATION!AI348 -> 0 | AL16: =SUM(D16:AK16) -> 0
C17: Destroy | D17: ='C.Grade'!I644 -> 0 | E17: ='C.Grade'!J644 -> 0 | F17: ='C.Grade'!K644 -> 0 | G17: ='C.Grade'!L644 -> 0 | H17: ='C.Grade'!M644 -> 0 | I17: ='C.Grade'!N644 -> 0 | J17: ='C.Grade'!O644 -> 0 | K17: ='C.Grade'!P644 -> 0 | ... AH17: ='C.Grade'!AM644 -> 0 | AK17: ='C.Grade'!AN644 -> 0 | AL17: =SUM(D17:AK17) -> 0
C18: Total | D18: =SUM(D15:D17) -> 0 | E18: =SUM(E15:E17) -> 0 | F18: =SUM(F15:F17) -> 0 | G18: =SUM(G15:G17) -> 0 | H18: =SUM(H15:H17) -> 0 | I18: =SUM(I15:I17) -> 0 | J18: =SUM(J15:J17) -> 0 | K18: =SUM(K15:K17) -> 0 | ... Q18: =SUM(Q15:Q17) -> 0 | S18: =SUM(S15:S17) -> 0 | T18: =SUM(T15:T17) -> 0 | U18: =SUM(U15:U17) -> 0 | V18: =SUM(V15:V17) -> 0 | W18: =SUM(W15:W17) -> 0 | X18: =SUM(X15:X17) -> 0 | Y18: =SUM(Y15:Y17) -> 0 | Z18: =SUM(Z15:Z17) -> 0 | ... AL18: =SUM(AL15:AL17) -> 0
C19: Total | D19: =D18 -> 0 | E19: =+E18+F18 -> 0 | G19: =G18 -> 0 | H19: =H18 -> 0 | I19: =I18 -> 0 | J19: =J18 -> 0 | K19: =K18 -> 0 | L19: =+L18+M18+N18+O18+Q18+S18+T18 -> 0 | U19: =+U18+V18+W18 -> 0 | X19: =X18 -> 0 | Y19: =Y18 -> 0 | Z19: =Z18 -> 0 | AA19: =+AA18+AB18+AC18 -> 0 | AD19: =AD18 -> 0 | AE19: =AE18 -> 0 | AF19: =AF18 -> 0 | AG19: =AG18 -> 0 | AH19: =AH18 -> 0 | AI19: =AI18 -> 0 | AJ19: =AJ18 -> 0 | AK19: =AK18 -> 0 | AL19: =AL18 -> 0
B20: Week 4 | C20: Outlet | D20: =B.Grade!H201 -> 0 | E20: =B.Grade!I201 -> 0 | F20: =B.Grade!J201 -> 0 | G20: =B.Grade!K201 -> 0 | I20: =B.Grade!N201 -> 0 | J20: =B.Grade!O201 -> 0 | K20: =B.Grade!P201 -> 0 | L20: =B.Grade!Q201 -> 0 | M20: =B.Grade!R201 -> 0 | N20: =B.Grade!S201 -> 0 | O20: =B.Grade!T201 -> 0 | P20: =B.Grade!U201 -> 0 | Q20: =B.Grade!V201 -> 0 | U20: =B.Grade!W201 -> 0 | V20: =B.Grade!X201 -> 0 | W20: =B.Grade!Y201 -> 0 | AI20: =B.Grade!L201 -> 0 | AK20: =B.Grade!Z201 -> 0 | AL20: =SUM(D20:AK20) -> 0
C21: Donation | D21: =DONATION!H361 -> 0 | E21: =DONATION!I361 -> 0 | F21: =DONATION!J361 -> 0 | G21: =DONATION!K361 -> 0 | H21: =DONATION!L361 -> 0 | I21: =DONATION!M361 -> 0 | J21: =DONATION!N361 -> 0 | K21: =DONATION!O361 -> 0 | ... Q21: =DONATION!U361 -> 0 | S21: =DONATION!W361 -> 0 | T21: =DONATION!X361 -> 0 | U21: =DONATION!Y361 -> 0 | V21: =DONATION!Z361 -> 0 | W21: =DONATION!AA361 -> 0 | X21: =DONATION!AB361 -> 0 | Y21: =DONATION!AC361 -> 0 | Z21: =DONATION!AD361 -> 0 | ... AB21: =DONATION!AF361 -> 0 | AC21: =DONATION!AI361 -> 0 | AD21: =DONATION!AJ361 -> 0 | AI21: =DONATION!AG361 -> 0 | AJ21: =DONATION!AH361 -> 0 | AK21: =DONATION!AI361 -> 0 | AL21: =SUM(D21:AK21) -> 0
C22: Destroy | D22: ='C.Grade'!I915 -> 0 | E22: ='C.Grade'!J915 -> 0 | F22: ='C.Grade'!K915 -> 0 | G22: ='C.Grade'!L915 -> 0 | H22: ='C.Grade'!M915 -> 0 | I22: ='C.Grade'!N915 -> 0 | J22: ='C.Grade'!O915 -> 0 | K22: ='C.Grade'!P915 -> 0 | ... AH22: ='C.Grade'!AM915 -> 0 | AK22: ='C.Grade'!AN915 -> 0 | AL22: =SUM(D22:AK22) -> 0
C23: Total | D23: =SUM(D20:D22) -> 0 | E23: =SUM(E20:E22) -> 0 | F23: =SUM(F20:F22) -> 0 | G23: =SUM(G20:G22) -> 0 | H23: =SUM(H20:H22) -> 0 | I23: =SUM(I20:I22) -> 0 | J23: =SUM(J20:J22) -> 0 | K23: =SUM(K20:K22) -> 0 | ... AL23: =SUM(AL20:AL22) -> 0
C24: Total | D24: =D23 -> 0 | E24: =+E23+F23 -> 0 | G24: =G23 -> 0 | H24: =H23 -> 0 | I24: =I23 -> 0 | J24: =J23 -> 0 | K24: =K23 -> 0 | L24: =+L23+M23+N23+O23+Q23+R23+S23+T23 -> 0 | U24: =+U23+V23+W23 -> 0 | X24: =X23 -> 0 | Y24: =Y23 -> 0 | Z24: =Z23 -> 0 | AA24: =+AA23+AB23+AC23 -> 0 | AD24: =AD23 -> 0 | AE24: =AE23 -> 0 | AF24: =AF23 -> 0 | AG24: =AG23 -> 0 | AK24: =AK23 -> 0 | AL24: =AL23 -> 0
B25: Week 5 | C25: Outlet | D25: =B.Grade!H234 -> 0 | E25: =B.Grade!I234 -> 0 | F25: =B.Grade!J234 -> 0 | G25: =B.Grade!K234 -> 0 | H25: =B.Grade!L234 -> 0 | I25: =B.Grade!N234 -> 0 | J25: =B.Grade!O234 -> 0 | K25: =B.Grade!P234 -> 0 | L25: =B.Grade!Q234 -> 0 | M25: =B.Grade!R234 -> 0 | N25: =B.Grade!S234 -> 0 | O25: =B.Grade!T234 -> 0 | P25: =B.Grade!U234 -> 0 | ... S25: =B.Grade!X234 -> 0 | T25: =B.Grade!V234 -> 0 | U25: =B.Grade!W234 -> 0 | V25: =B.Grade!X234 -> 0 | W25: =B.Grade!Y234 -> 0 | AK25: =B.Grade!Z234 -> 0 | AL25: =SUM(D25:AK25) -> 0
C26: Donation | D26: =DONATION!H406 -> 0 | E26: =DONATION!I406 -> 0 | F26: =DONATION!J406 -> 0 | G26: =DONATION!K406 -> 0 | H26: =DONATION!L406 -> 0 | I26: =DONATION!M406 -> 0 | J26: =DONATION!N406 -> 0 | K26: =DONATION!O406 -> 0 | ... P26: =DONATION!T406 -> 0 | Q26: =DONATION!T406 -> 0 | R26: =DONATION!U406 -> 0 | S26: =DONATION!U406 -> 0 | T26: =DONATION!V406 -> 0 | U26: =DONATION!W406 -> 0 | V26: =DONATION!X406 -> 0 | W26: =DONATION!Y406 -> 0 | X26: =DONATION!Z406 -> 0 | Y26: =DONATION!AA406 -> 0 | Z26: =DONATION!AB406 -> 0 | ... AD26: =DONATION!AF406 -> 0 | AK26: =DONATION!AI406 -> 0 | AL26: =SUM(D26:AK26) -> 0
C27: Destroy | D27: ='C.Grade'!I1118 -> 0 | E27: ='C.Grade'!J1118 -> 0 | F27: ='C.Grade'!K1118 -> 0 | G27: ='C.Grade'!L1118 -> 0 | H27: ='C.Grade'!M1118 -> 0 | I27: ='C.Grade'!N1118 -> 0 | J27: ='C.Grade'!O1118 -> 0 | K27: ='C.Grade'!P1118 -> 0 | ... AI27: ='C.Grade'!AN1118 -> 0 | AK27: ='C.Grade'!AN1118 -> 0 | AL27: =SUM(D27:AK27) -> 0
C28: Total | D28: =SUM(D25:D27) -> 0 | E28: =SUM(E25:E27) -> 0 | F28: =SUM(F25:F27) -> 0 | G28: =SUM(G25:G27) -> 0 | H28: =SUM(H25:H27) -> 0 | I28: =SUM(I25:I27) -> 0 | J28: =SUM(J25:J27) -> 0 | K28: =SUM(K25:K27) -> 0 | ... AL28: =SUM(AL25:AL27) -> 0
C29: Total | D29: =D28 -> 0 | E29: =+E28+F28 -> 0 | G29: =G28 -> 0 | H29: =H28 -> 0 | I29: =I28 -> 0 | J29: =J28 -> 0 | K29: =K28 -> 0 | L29: =+L28+M28+N28+O28+Q28+S28+T28 -> 0 | U29: =+U28+V28+W28 -> 0 | X29: =X28 -> 0 | Y29: =Y28 -> 0 | Z29: =Z28 -> 0 | AA29: =+AA28+AB28+AC28 -> 0 | AD29: =AD28 -> 0 | AE29: =AE28 -> 0 | AF29: =AF28 -> 0 | AG29: =AG28 -> 0 | AH29: =AH28 -> 0 | AI29: =AI28 -> 0 | AJ29: =AJ28 -> 0 | AK29: =AK28 -> 0 | AL29: =AL28 -> 0
B30: GRAND TOTAL | D30: =D8+D13+D18+D23+D28 -> 3.5 | E30: =E8+E13+E18+E23+E28 -> 0 | F30: =F8+F13+F18+F23+F28 -> 2 | G30: =G8+G13+G18+G23+G28 -> 0 | H30: =H8+H13+H18+H23+H28 -> 1 | I30: =I8+I13+I18+I23+I28 -> 0 | J30: =J8+J13+J18+J23+J28 -> 11 | K30: =K8+K13+K18+K23+K28 -> 9.5 | ... O30: =O8+O13+O18+O23+O28 -> 0 | Q30: =Q8+Q13+Q18+Q23+Q28 -> 0 | S30: =S8+S13+S18+S23+S28 -> 0 | T30: =T8+T13+T18+T23+T28 -> 0 | U30: =U8+U13+U18+U23+U28 -> 0 | V30: =V8+V13+V18+V23+V28 -> 0 | W30: =W8+W13+W18+W23+W28 -> 5 | X30: =X8+X13+X18+X23+X28 -> 16.5 | Y30: =Y8+Y13+Y18+Y23+Y28 -> 0 | Z30: =Z8+Z13+Z18+Z23+Z28 -> 0 | ... AL30: =AL8+AL13+AL18+AL23+AL28 -> 57
B31: GRAND TOTAL | D31: =D30 -> 3.5 | E31: =+E30+F30 -> 2 | G31: =G30 -> 0 | H31: =H30 -> 1 | I31: =I30 -> 0 | J31: =J30 -> 11 | K31: =K30 -> 9.5 | L31: =L30+M30+N30+O30+Q30+S30+T30 -> 6.5 | U31: =+U30+V30+W30 -> 5 | X31: =X30 -> 16.5 | Y31: =Y30 -> 0 | Z31: =Z30 -> 0 | AA31: =+AA30+AB30+AC30 -> 0 | AD31: =AD30 -> 0 | AE31: =AE30 -> 0 | AF31: =AF30 -> 0 | AG31: =AG30 -> 0 | AH31: =AH30 -> 0 | AI31: =AI30 -> 0 | AJ31: =AJ30 -> 0 | AK31: =AK30 -> 0 | AL31: =AL30 -> 57
D34: 1st Week | F34: 2nd Week | H34: 3rd Week | J34: 4th Week | L34: 5th week | N34: TOTAL
D35: Prs | E35: % | F35: Prs | G35: % | H35: Prs | I35: % | J35: Prs | K35: % | L35: Prs | M35: % | N35: Prs | O35: %
C36: Outlet | D36: =AL5 -> 0 | E36: =D36/D40 -> 0 | F36: =AL10 -> 0 | G36: =F36/F40 -> 0 | H36: =AL15 -> 0 | I36: =H36/H40 -> #DIV/0! | J36: =AL20 -> 0 | K36: =J36/J40 -> 0 | L36: =AL26 -> 0 | M36: =L36/L40 -> 0 | N36: =+D36+F36+H36+J36+L36 -> 0 | O36: =N36/N40 -> 0
C37: Donasi | D37: =AL6 -> 0 | E37: =D37/D40 -> 0 | F37: =AL11 -> 0 | G37: =F37/F40 -> 0 | H37: =AL16 -> 0 | I37: =H37/H40 -> #DIV/0! | J37: =AL21 -> 0 | K37: =J37/J40 -> 0 | L37: =AL27 -> 0 | M37: =L37/L40 -> 0 | N37: =+D37+F37+H37+J37+L37 -> 0 | O37: =N37/N40 -> 0
C38: Destroy | D38: =AL7 -> 36 | E38: =D38/D40 -> 0.5 | F38: =AL12 -> 21 | G38: =F38/F40 -> 0.5 | H38: =AL17 -> 0 | I38: =H38/H40 -> #DIV/0! | J38: =AL22 -> 0 | K38: =J38/J40 -> 0 | L38: =AL28 -> 0 | M38: =L38/L40 -> 0 | N38: =+D38+F38+H38+J38+L38 -> 57 | O38: =N38/N40 -> 0.5
C39: A-Grade | D39: =AL8 -> 36 | E39: =D39/D40 -> 0.5 | F39: =AL13 -> 21 | G39: =F39/F40 -> 0.5 | H39: =AL18 -> 0 | I39: =H39/H40 -> #DIV/0! | J39: =AL23 -> 0 | K39: =J39/J40 -> 0 | L39: =AL29 -> 0 | M39: =L39/L40 -> 0 | N39: =+D39+F39+H39+J39+L39 -> 57 | O39: =N39/N40 -> 0.5
C40: Total Production | D40: =SUM(D36:D39) -> 72 | F40: =SUM(F36:F39) -> 42 | H40: =SUM(H36:H39) -> 0 | J40: =SUM(J36:J40) -> 0 | L40: =SUM(L36:L40) -> 0 | N40: =SUM(N36:N39) -> 114

Sheet Summary by Model 
A2: Outlet | T2: Donation | AM2: DESTROY
AN3: Sep '21
A4: Line | B4: Tanggal | C4: Model Name | D4: Color | E4: 3 | F4: 4 | G4: 5 | H4: 6 | I4: 7 | J4: 8 | K4: 9 | L4: 10 | M4: 11 | N4: 12 | O4: 13 | P4: 14 | Q4: Total | R4: Total Per-hari | T4: Line | U4: Tanggal | V4: Model Name | W4: Color | X4: 3 | Y4: 4 | Z4: 5 | AA4: 6 | AB4: 7 | AC4: 8 | AD4: 9 | AE4: 10 | AF4: 11 | AG4: 12 | AH4: 13 | AI4: 14 | AJ4: Total | AK4: Total Per-hari | AM4: Line | AN4: Tanggal | AO4: Model Name | AP4: Color | AQ4: 3 | AR4: 4 | AS4: 5 | AT4: 6 | AU4: 7 | AV4: 8 | AW4: 9 | AX4: 10 | AY4: 11 | AZ4: 12 | BA4: 13 | BB4: 14 | BC4: Total | BD4: Total Per-hari
E5: 7 | F5: 8 | G5: 9 | H5: 10 | I5: 11 | J5: 12 | K5: 13 | L5: 1 | M5: 2 | N5: 3 | O5: 4 | P5: 5 | X5: 7 | Y5: 8 | Z5: 9 | AA5: 10 | AB5: 11 | AC5: 12 | AD5: 13 | AE5: 1 | AF5: 2 | AG5: 3 | AH5: 4 | AI5: 5 | AQ5: 7 | AR5: 8 | AS5: 9 | AT5: 10 | AU5: 11 | AV5: 12 | AW5: 13 | AX5: 1 | AY5: 2 | AZ5: 3 | BA5: 4 | BB5: 5
E6: S | F6: SS | G6: M | H6: L | I6: LL | J6: 3L | K6: 4L | X6: S | Y6: SS | Z6: M | AA6: L | AB6: LL | AC6: 3L | AD6: 4L | AQ6: S | AR6: SS | AS6: M | AT6: L | AU6: LL | AV6: 3L | AW6: 4L
Q8: =SUM(E8:P8) -> 0 | R8: =SUM(Q8:Q9) -> 0 | AJ8: =SUM(X8:AI8) -> 0 | AK8: =SUM(AJ8:AJ9) -> 0 | BC8: =SUM(AQ8:BB8) -> 0
Q9: =SUM(E9:P9) -> 0 | AJ9: =SUM(X9:AI9) -> 0 | AK9: =SUM(AJ9:AJ17) -> 0 | BC9: =SUM(AQ9:BB9) -> 0
Q10: =SUM(E10:P10) -> 0 | BC10: =SUM(AQ10:BB10) -> 0
Q11: =SUM(E11:P11) -> 0 | AJ11: =SUM(X11:AI11) -> 0 | BC11: =SUM(AQ11:BB11) -> 0
Q12: =SUM(E12:P12) -> 0 | AJ12: =SUM(X12:AI12) -> 0 | BC12: =SUM(AQ12:BB12) -> 0
Q13: =SUM(E13:P13) -> 0 | R13: =SUM(Q13:Q16) -> 0 | AJ13: =SUM(X13:AI13) -> 0 | BC13: =SUM(AQ13:BB13) -> 0 | BD13: =SUM(BC13:BC18) -> 0
Q14: =SUM(E14:P14) -> 0 | AJ14: =SUM(X14:AI14) -> 0 | BC14: =SUM(AQ14:BB14) -> 0
BC15: =SUM(AQ15:BB15) -> 0
Q16: =SUM(E16:P16) -> 0 | AJ16: =SUM(X16:AI16) -> 0 | BC16: =SUM(AQ16:BB16) -> 0
Q17: =SUM(E17:P17) -> 0 | BC17: =SUM(AQ17:BB17) -> 0
Q18: =SUM(E18:P18) -> 0 | AJ18: =SUM(X18:AI18) -> 0 | AK18: =SUM(AJ18:AJ19) -> 0 | BC18: =SUM(AQ18:BB18) -> 0
Q19: =SUM(E19:P19) -> 0 | AJ19: =SUM(X19:AI19) -> 0 | BC19: =SUM(AQ19:BB19) -> 0 | BD19: =SUM(BC19:BC22) -> 0
Q20: =SUM(E20:P20) -> 0 | R20: 0 | AJ20: =SUM(X20:AI20) -> 0 | AK20: =SUM(AJ20:AJ21) -> 0 | BC20: =SUM(AQ20:BB20) -> 0
Q21: =SUM(E21:P21) -> 0 | R21: 0 | AJ21: =SUM(X21:AI21) -> 0 | BC21: =SUM(AQ21:BB21) -> 0
Q22: =SUM(E22:P22) -> 0 | R22: 0 | AJ22: =SUM(X22:AI22) -> 0 | AK22: =SUM(AJ22:AJ23) -> 0 | BC22: =SUM(AQ22:BB22) -> 0
Q23: =SUM(E23:P23) -> 0 | R23: 0 | AJ23: =SUM(X23:AI23) -> 0 | BC23: =SUM(AQ23:BB23) -> 0 | BD23: =SUM(BC23:BC25) -> 0
Q24: =SUM(E24:P24) -> 0 | R24: 0 | AJ24: =SUM(X24:AI24) -> 0 | AK24: =SUM(AJ24:AJ25) -> 0 | BC24: =SUM(AQ24:BB24) -> 0
Q25: =SUM(E25:P25) -> 0 | R25: 0 | AJ25: =SUM(X25:AI25) -> 0 | BC25: =SUM(AQ25:BB25) -> 0
Q26: =SUM(E26:P26) -> 0 | AJ26: =SUM(X26:AI26) -> 0 | AK26: =SUM(AJ26:AJ30) -> 0 | BC26: =SUM(AQ26:BB26) -> 0 | BD26: =SUM(BC26:BC30) -> 0
Q27: =SUM(E27:P27) -> 0 | AJ27: =SUM(X27:AI27) -> 0 | BC27: =SUM(AQ27:BB27) -> 0
Q28: =SUM(E28:P28) -> 0 | AJ28: =SUM(X28:AI28) -> 0 | BC28: =SUM(AQ28:BB28) -> 0
Q29: =SUM(E29:P29) -> 0 | AJ29: =SUM(X29:AI29) -> 0 | BC29: =SUM(AQ29:BB29) -> 0
Q30: =SUM(E30:P30) -> 0 | AJ30: =SUM(X30:AI30) -> 0 | BC30: =SUM(AQ30:BB30) -> 0
Q31: =SUM(E31:P31) -> 0 | R31: =SUM(Q31:Q35) -> 0 | AJ31: =SUM(X31:AI31) -> 0 | BC31: =SUM(AQ31:BB31) -> 0 | BD31: =SUM(BC31:BC34) -> 0
Q32: =SUM(E32:P32) -> 0 | AJ32: =SUM(X32:AI32) -> 0 | BC32: =SUM(AQ32:BB32) -> 0
Q33: =SUM(E33:P33) -> 0 | AJ33: =SUM(X33:AI33) -> 0 | BC33: =SUM(AQ33:BB33) -> 0
Q34: =SUM(E34:P34) -> 0 | AJ34: =SUM(X34:AI34) -> 0 | BC34: =SUM(AQ34:BB34) -> 0
Q35: =SUM(E35:P35) -> 0 | AJ35: =SUM(X35:AI35) -> 0 | BC35: =SUM(AQ35:BB35) -> 0
Q36: =SUM(E36:P36) -> 0 | AJ36: =SUM(X36:AI36) -> 0 | BC36: =SUM(AQ36:BB36) -> 0
Q37: =SUM(E37:P37) -> 0 | AJ37: =SUM(X37:AI37) -> 0 | BC37: =SUM(AQ37:BB37) -> 0
Q38: =SUM(E38:P38) -> 0 | AJ38: =SUM(X38:AI38) -> 0 | BC38: =SUM(AQ38:BB38) -> 0
Q39: =SUM(E39:P39) -> 0 | AJ39: =SUM(X39:AI39) -> 0 | BC39: =SUM(AQ39:BB39) -> 0
Q40: =SUM(E40:P40) -> 0 | AJ40: =SUM(X40:AI40) -> 0 | BC40: =SUM(AQ40:BB40) -> 0
Q41: =SUM(E41:P41) -> 0 | AJ41: =SUM(X41:AI41) -> 0 | BC41: =SUM(AQ41:BB41) -> 0
Q42: =SUM(E42:P42) -> 0 | R42: 0 | AJ42: =SUM(X42:AI42) -> 0 | BC42: =SUM(AQ42:BB42) -> 0
...
